2025-03-15 16:27:32,607 - root - ‚ÑπÔ∏è INFO - main.py:70 - Initializing pipeline
2025-03-15 16:27:32,607 - root - ‚ÑπÔ∏è INFO - main.py:14 - Starting Twitter scraper for @LBCI_NEWS
2025-03-15 16:27:37,474 - root - ‚ÑπÔ∏è INFO - core.py:25 - üöÄ Starting scrape for @LBCI_NEWS
2025-03-15 16:27:41,783 - root - ‚ÑπÔ∏è INFO - core.py:75 - üì¶ Collected 4 new tweets (Total: 4)
2025-03-15 16:27:42,510 - root - ‚ÑπÔ∏è INFO - core.py:75 - üì¶ Collected 1 new tweets (Total: 5)
2025-03-15 16:27:43,319 - root - ‚ÑπÔ∏è INFO - core.py:75 - üì¶ Collected 3 new tweets (Total: 8)
2025-03-15 16:27:44,038 - root - ‚ÑπÔ∏è INFO - producer.py:22 - Sent batch of 10 tweets (Total: 10)
2025-03-15 16:27:44,038 - root - ‚ÑπÔ∏è INFO - core.py:75 - üì¶ Collected 2 new tweets (Total: 10)
2025-03-15 16:27:44,991 - root - ‚ÑπÔ∏è INFO - core.py:75 - üì¶ Collected 6 new tweets (Total: 16)
2025-03-15 16:27:45,659 - root - ‚ö†Ô∏è WARNING - core.py:77 - ‚ö†Ô∏è  No new tweets in loaded content
2025-03-15 16:27:45,659 - root - ‚ö†Ô∏è WARNING - core.py:82 - ‚è≥ Retry #1 for 2s
2025-03-15 16:27:48,610 - root - ‚ÑπÔ∏è INFO - core.py:75 - üì¶ Collected 3 new tweets (Total: 19)
2025-03-15 16:27:49,475 - root - ‚ÑπÔ∏è INFO - producer.py:22 - Sent batch of 10 tweets (Total: 20)
2025-03-15 16:27:49,477 - root - ‚ÑπÔ∏è INFO - core.py:75 - üì¶ Collected 4 new tweets (Total: 23)
2025-03-15 16:27:50,357 - root - ‚ÑπÔ∏è INFO - core.py:75 - üì¶ Collected 3 new tweets (Total: 26)
2025-03-15 16:27:51,203 - root - ‚ÑπÔ∏è INFO - producer.py:22 - Sent batch of 10 tweets (Total: 30)
2025-03-15 16:27:51,204 - root - ‚ÑπÔ∏è INFO - core.py:75 - üì¶ Collected 4 new tweets (Total: 30)
2025-03-15 16:27:52,242 - root - ‚ÑπÔ∏è INFO - core.py:75 - üì¶ Collected 2 new tweets (Total: 32)
2025-03-15 16:27:53,309 - root - ‚ÑπÔ∏è INFO - core.py:75 - üì¶ Collected 4 new tweets (Total: 36)
2025-03-15 16:27:54,201 - root - ‚ÑπÔ∏è INFO - core.py:75 - üì¶ Collected 2 new tweets (Total: 38)
2025-03-15 16:27:54,963 - root - ‚ÑπÔ∏è INFO - core.py:75 - üì¶ Collected 1 new tweets (Total: 39)
2025-03-15 16:27:56,165 - root - ‚ÑπÔ∏è INFO - producer.py:22 - Sent batch of 10 tweets (Total: 40)
2025-03-15 16:27:56,168 - root - ‚ÑπÔ∏è INFO - core.py:75 - üì¶ Collected 5 new tweets (Total: 44)
2025-03-15 16:27:57,270 - root - ‚ÑπÔ∏è INFO - core.py:75 - üì¶ Collected 3 new tweets (Total: 47)
2025-03-15 16:27:58,024 - root - ‚ÑπÔ∏è INFO - producer.py:22 - Sent batch of 10 tweets (Total: 50)
2025-03-15 16:27:58,024 - root - ‚ÑπÔ∏è INFO - core.py:75 - üì¶ Collected 3 new tweets (Total: 50)
2025-03-15 16:28:00,075 - root - ‚ÑπÔ∏è INFO - core.py:93 - ‚úÖ Final count: 50/50 tweets
2025-03-15 16:28:00,075 - root - ‚ÑπÔ∏è INFO - core.py:95 - üéØ Target reached successfully
2025-03-15 16:28:00,076 - root - ‚ÑπÔ∏è INFO - main.py:22 - Scraping completed for @LBCI_NEWS
2025-03-15 16:28:00,076 - root - ‚ÑπÔ∏è INFO - producer.py:29 - Final count: 50 tweets sent
2025-03-15 16:28:00,077 - src.kafka.consumers.pipeline - ‚ÑπÔ∏è INFO - pipeline.py:215 - Starting Storage Consumer...
2025-03-15 16:28:03,120 - src.models.relational.tweets - ‚ÑπÔ∏è INFO - tweets.py:42 - Platforms already exist.
2025-03-15 16:28:03,123 - src.kafka.consumers.pipeline - ‚ùå ERROR - pipeline.py:75 - Error processing message: Commands out of sync; you can't run this command now
Traceback (most recent call last):
  File "C:\Users\Admin\PycharmProjects\SocialMediaPipeline\src\kafka\consumers\pipeline.py", line 60, in process_message
    self.tweet_model.insert_post_and_engagement_metrics(
  File "C:\Users\Admin\PycharmProjects\SocialMediaPipeline\src\models\relational\tweets.py", line 131, in insert_post_and_engagement_metrics
    self.execute_query(insert_post_query, params)
  File "C:\Users\Admin\PycharmProjects\SocialMediaPipeline\src\models\relational\tweets.py", line 59, in execute_query
    connection.commit()
  File "C:\Users\Admin\PycharmProjects\SocialMediaPipeline\.venv\Lib\site-packages\mysql\connector\connection_cext.py", line 609, in commit
    self._cmysql.commit()
_mysql_connector.MySQLInterfaceError: Commands out of sync; you can't run this command now
2025-03-15 16:28:03,127 - src.models.relational.tweets - ‚ÑπÔ∏è INFO - tweets.py:42 - Platforms already exist.
2025-03-15 16:28:03,129 - src.kafka.consumers.pipeline - ‚ùå ERROR - pipeline.py:75 - Error processing message: Commands out of sync; you can't run this command now
Traceback (most recent call last):
  File "C:\Users\Admin\PycharmProjects\SocialMediaPipeline\src\kafka\consumers\pipeline.py", line 60, in process_message
    self.tweet_model.insert_post_and_engagement_metrics(
  File "C:\Users\Admin\PycharmProjects\SocialMediaPipeline\src\models\relational\tweets.py", line 131, in insert_post_and_engagement_metrics
    self.execute_query(insert_post_query, params)
  File "C:\Users\Admin\PycharmProjects\SocialMediaPipeline\src\models\relational\tweets.py", line 59, in execute_query
    connection.commit()
  File "C:\Users\Admin\PycharmProjects\SocialMediaPipeline\.venv\Lib\site-packages\mysql\connector\connection_cext.py", line 609, in commit
    self._cmysql.commit()
_mysql_connector.MySQLInterfaceError: Commands out of sync; you can't run this command now
2025-03-15 16:28:03,133 - src.models.relational.tweets - ‚ÑπÔ∏è INFO - tweets.py:42 - Platforms already exist.
2025-03-15 16:28:03,134 - src.kafka.consumers.pipeline - ‚ùå ERROR - pipeline.py:75 - Error processing message: Commands out of sync; you can't run this command now
Traceback (most recent call last):
  File "C:\Users\Admin\PycharmProjects\SocialMediaPipeline\src\kafka\consumers\pipeline.py", line 60, in process_message
    self.tweet_model.insert_post_and_engagement_metrics(
  File "C:\Users\Admin\PycharmProjects\SocialMediaPipeline\src\models\relational\tweets.py", line 131, in insert_post_and_engagement_metrics
    self.execute_query(insert_post_query, params)
  File "C:\Users\Admin\PycharmProjects\SocialMediaPipeline\src\models\relational\tweets.py", line 59, in execute_query
    connection.commit()
  File "C:\Users\Admin\PycharmProjects\SocialMediaPipeline\.venv\Lib\site-packages\mysql\connector\connection_cext.py", line 609, in commit
    self._cmysql.commit()
_mysql_connector.MySQLInterfaceError: Commands out of sync; you can't run this command now
2025-03-15 16:28:03,136 - src.models.relational.tweets - ‚ÑπÔ∏è INFO - tweets.py:42 - Platforms already exist.
2025-03-15 16:28:03,138 - src.kafka.consumers.pipeline - ‚ùå ERROR - pipeline.py:75 - Error processing message: Commands out of sync; you can't run this command now
Traceback (most recent call last):
  File "C:\Users\Admin\PycharmProjects\SocialMediaPipeline\src\kafka\consumers\pipeline.py", line 60, in process_message
    self.tweet_model.insert_post_and_engagement_metrics(
  File "C:\Users\Admin\PycharmProjects\SocialMediaPipeline\src\models\relational\tweets.py", line 131, in insert_post_and_engagement_metrics
    self.execute_query(insert_post_query, params)
  File "C:\Users\Admin\PycharmProjects\SocialMediaPipeline\src\models\relational\tweets.py", line 59, in execute_query
    connection.commit()
  File "C:\Users\Admin\PycharmProjects\SocialMediaPipeline\.venv\Lib\site-packages\mysql\connector\connection_cext.py", line 609, in commit
    self._cmysql.commit()
_mysql_connector.MySQLInterfaceError: Commands out of sync; you can't run this command now
2025-03-15 16:28:03,140 - src.models.relational.tweets - ‚ÑπÔ∏è INFO - tweets.py:42 - Platforms already exist.
2025-03-15 16:28:03,142 - src.kafka.consumers.pipeline - ‚ùå ERROR - pipeline.py:75 - Error processing message: Commands out of sync; you can't run this command now
Traceback (most recent call last):
  File "C:\Users\Admin\PycharmProjects\SocialMediaPipeline\src\kafka\consumers\pipeline.py", line 60, in process_message
    self.tweet_model.insert_post_and_engagement_metrics(
  File "C:\Users\Admin\PycharmProjects\SocialMediaPipeline\src\models\relational\tweets.py", line 131, in insert_post_and_engagement_metrics
    self.execute_query(insert_post_query, params)
  File "C:\Users\Admin\PycharmProjects\SocialMediaPipeline\src\models\relational\tweets.py", line 59, in execute_query
    connection.commit()
  File "C:\Users\Admin\PycharmProjects\SocialMediaPipeline\.venv\Lib\site-packages\mysql\connector\connection_cext.py", line 609, in commit
    self._cmysql.commit()
_mysql_connector.MySQLInterfaceError: Commands out of sync; you can't run this command now
2025-03-15 16:28:03,145 - src.models.relational.tweets - ‚ÑπÔ∏è INFO - tweets.py:42 - Platforms already exist.
2025-03-15 16:28:03,146 - src.kafka.consumers.pipeline - ‚ùå ERROR - pipeline.py:75 - Error processing message: Commands out of sync; you can't run this command now
Traceback (most recent call last):
  File "C:\Users\Admin\PycharmProjects\SocialMediaPipeline\src\kafka\consumers\pipeline.py", line 60, in process_message
    self.tweet_model.insert_post_and_engagement_metrics(
  File "C:\Users\Admin\PycharmProjects\SocialMediaPipeline\src\models\relational\tweets.py", line 131, in insert_post_and_engagement_metrics
    self.execute_query(insert_post_query, params)
  File "C:\Users\Admin\PycharmProjects\SocialMediaPipeline\src\models\relational\tweets.py", line 59, in execute_query
    connection.commit()
  File "C:\Users\Admin\PycharmProjects\SocialMediaPipeline\.venv\Lib\site-packages\mysql\connector\connection_cext.py", line 609, in commit
    self._cmysql.commit()
_mysql_connector.MySQLInterfaceError: Commands out of sync; you can't run this command now
2025-03-15 16:28:03,150 - src.models.relational.tweets - ‚ÑπÔ∏è INFO - tweets.py:42 - Platforms already exist.
2025-03-15 16:28:03,151 - src.kafka.consumers.pipeline - ‚ùå ERROR - pipeline.py:75 - Error processing message: Commands out of sync; you can't run this command now
Traceback (most recent call last):
  File "C:\Users\Admin\PycharmProjects\SocialMediaPipeline\src\kafka\consumers\pipeline.py", line 60, in process_message
    self.tweet_model.insert_post_and_engagement_metrics(
  File "C:\Users\Admin\PycharmProjects\SocialMediaPipeline\src\models\relational\tweets.py", line 131, in insert_post_and_engagement_metrics
    self.execute_query(insert_post_query, params)
  File "C:\Users\Admin\PycharmProjects\SocialMediaPipeline\src\models\relational\tweets.py", line 59, in execute_query
    connection.commit()
  File "C:\Users\Admin\PycharmProjects\SocialMediaPipeline\.venv\Lib\site-packages\mysql\connector\connection_cext.py", line 609, in commit
    self._cmysql.commit()
_mysql_connector.MySQLInterfaceError: Commands out of sync; you can't run this command now
2025-03-15 16:28:03,154 - src.models.relational.tweets - ‚ÑπÔ∏è INFO - tweets.py:42 - Platforms already exist.
2025-03-15 16:28:03,155 - src.kafka.consumers.pipeline - ‚ùå ERROR - pipeline.py:75 - Error processing message: Commands out of sync; you can't run this command now
Traceback (most recent call last):
  File "C:\Users\Admin\PycharmProjects\SocialMediaPipeline\src\kafka\consumers\pipeline.py", line 60, in process_message
    self.tweet_model.insert_post_and_engagement_metrics(
  File "C:\Users\Admin\PycharmProjects\SocialMediaPipeline\src\models\relational\tweets.py", line 131, in insert_post_and_engagement_metrics
    self.execute_query(insert_post_query, params)
  File "C:\Users\Admin\PycharmProjects\SocialMediaPipeline\src\models\relational\tweets.py", line 59, in execute_query
    connection.commit()
  File "C:\Users\Admin\PycharmProjects\SocialMediaPipeline\.venv\Lib\site-packages\mysql\connector\connection_cext.py", line 609, in commit
    self._cmysql.commit()
_mysql_connector.MySQLInterfaceError: Commands out of sync; you can't run this command now
2025-03-15 16:28:03,158 - src.models.relational.tweets - ‚ÑπÔ∏è INFO - tweets.py:42 - Platforms already exist.
2025-03-15 16:28:03,159 - src.kafka.consumers.pipeline - ‚ùå ERROR - pipeline.py:75 - Error processing message: Commands out of sync; you can't run this command now
Traceback (most recent call last):
  File "C:\Users\Admin\PycharmProjects\SocialMediaPipeline\src\kafka\consumers\pipeline.py", line 60, in process_message
    self.tweet_model.insert_post_and_engagement_metrics(
  File "C:\Users\Admin\PycharmProjects\SocialMediaPipeline\src\models\relational\tweets.py", line 131, in insert_post_and_engagement_metrics
    self.execute_query(insert_post_query, params)
  File "C:\Users\Admin\PycharmProjects\SocialMediaPipeline\src\models\relational\tweets.py", line 59, in execute_query
    connection.commit()
  File "C:\Users\Admin\PycharmProjects\SocialMediaPipeline\.venv\Lib\site-packages\mysql\connector\connection_cext.py", line 609, in commit
    self._cmysql.commit()
_mysql_connector.MySQLInterfaceError: Commands out of sync; you can't run this command now
2025-03-15 16:28:03,163 - src.models.relational.tweets - ‚ÑπÔ∏è INFO - tweets.py:42 - Platforms already exist.
2025-03-15 16:28:03,164 - src.kafka.consumers.pipeline - ‚ùå ERROR - pipeline.py:75 - Error processing message: Commands out of sync; you can't run this command now
Traceback (most recent call last):
  File "C:\Users\Admin\PycharmProjects\SocialMediaPipeline\src\kafka\consumers\pipeline.py", line 60, in process_message
    self.tweet_model.insert_post_and_engagement_metrics(
  File "C:\Users\Admin\PycharmProjects\SocialMediaPipeline\src\models\relational\tweets.py", line 131, in insert_post_and_engagement_metrics
    self.execute_query(insert_post_query, params)
  File "C:\Users\Admin\PycharmProjects\SocialMediaPipeline\src\models\relational\tweets.py", line 59, in execute_query
    connection.commit()
  File "C:\Users\Admin\PycharmProjects\SocialMediaPipeline\.venv\Lib\site-packages\mysql\connector\connection_cext.py", line 609, in commit
    self._cmysql.commit()
_mysql_connector.MySQLInterfaceError: Commands out of sync; you can't run this command now
2025-03-15 16:28:03,166 - src.models.relational.tweets - ‚ÑπÔ∏è INFO - tweets.py:42 - Platforms already exist.
2025-03-15 16:28:03,168 - src.kafka.consumers.pipeline - ‚ùå ERROR - pipeline.py:75 - Error processing message: Commands out of sync; you can't run this command now
Traceback (most recent call last):
  File "C:\Users\Admin\PycharmProjects\SocialMediaPipeline\src\kafka\consumers\pipeline.py", line 60, in process_message
    self.tweet_model.insert_post_and_engagement_metrics(
  File "C:\Users\Admin\PycharmProjects\SocialMediaPipeline\src\models\relational\tweets.py", line 131, in insert_post_and_engagement_metrics
    self.execute_query(insert_post_query, params)
  File "C:\Users\Admin\PycharmProjects\SocialMediaPipeline\src\models\relational\tweets.py", line 59, in execute_query
    connection.commit()
  File "C:\Users\Admin\PycharmProjects\SocialMediaPipeline\.venv\Lib\site-packages\mysql\connector\connection_cext.py", line 609, in commit
    self._cmysql.commit()
_mysql_connector.MySQLInterfaceError: Commands out of sync; you can't run this command now
2025-03-15 16:28:03,171 - src.models.relational.tweets - ‚ÑπÔ∏è INFO - tweets.py:42 - Platforms already exist.
2025-03-15 16:28:03,172 - src.kafka.consumers.pipeline - ‚ùå ERROR - pipeline.py:75 - Error processing message: Commands out of sync; you can't run this command now
Traceback (most recent call last):
  File "C:\Users\Admin\PycharmProjects\SocialMediaPipeline\src\kafka\consumers\pipeline.py", line 60, in process_message
    self.tweet_model.insert_post_and_engagement_metrics(
  File "C:\Users\Admin\PycharmProjects\SocialMediaPipeline\src\models\relational\tweets.py", line 131, in insert_post_and_engagement_metrics
    self.execute_query(insert_post_query, params)
  File "C:\Users\Admin\PycharmProjects\SocialMediaPipeline\src\models\relational\tweets.py", line 59, in execute_query
    connection.commit()
  File "C:\Users\Admin\PycharmProjects\SocialMediaPipeline\.venv\Lib\site-packages\mysql\connector\connection_cext.py", line 609, in commit
    self._cmysql.commit()
_mysql_connector.MySQLInterfaceError: Commands out of sync; you can't run this command now
2025-03-15 16:28:03,174 - src.models.relational.tweets - ‚ÑπÔ∏è INFO - tweets.py:42 - Platforms already exist.
2025-03-15 16:28:03,177 - src.kafka.consumers.pipeline - ‚ùå ERROR - pipeline.py:75 - Error processing message: Commands out of sync; you can't run this command now
Traceback (most recent call last):
  File "C:\Users\Admin\PycharmProjects\SocialMediaPipeline\src\kafka\consumers\pipeline.py", line 60, in process_message
    self.tweet_model.insert_post_and_engagement_metrics(
  File "C:\Users\Admin\PycharmProjects\SocialMediaPipeline\src\models\relational\tweets.py", line 131, in insert_post_and_engagement_metrics
    self.execute_query(insert_post_query, params)
  File "C:\Users\Admin\PycharmProjects\SocialMediaPipeline\src\models\relational\tweets.py", line 59, in execute_query
    connection.commit()
  File "C:\Users\Admin\PycharmProjects\SocialMediaPipeline\.venv\Lib\site-packages\mysql\connector\connection_cext.py", line 609, in commit
    self._cmysql.commit()
_mysql_connector.MySQLInterfaceError: Commands out of sync; you can't run this command now
2025-03-15 16:28:03,179 - src.models.relational.tweets - ‚ÑπÔ∏è INFO - tweets.py:42 - Platforms already exist.
2025-03-15 16:28:03,180 - src.kafka.consumers.pipeline - ‚ùå ERROR - pipeline.py:75 - Error processing message: Commands out of sync; you can't run this command now
Traceback (most recent call last):
  File "C:\Users\Admin\PycharmProjects\SocialMediaPipeline\src\kafka\consumers\pipeline.py", line 60, in process_message
    self.tweet_model.insert_post_and_engagement_metrics(
  File "C:\Users\Admin\PycharmProjects\SocialMediaPipeline\src\models\relational\tweets.py", line 131, in insert_post_and_engagement_metrics
    self.execute_query(insert_post_query, params)
  File "C:\Users\Admin\PycharmProjects\SocialMediaPipeline\src\models\relational\tweets.py", line 59, in execute_query
    connection.commit()
  File "C:\Users\Admin\PycharmProjects\SocialMediaPipeline\.venv\Lib\site-packages\mysql\connector\connection_cext.py", line 609, in commit
    self._cmysql.commit()
_mysql_connector.MySQLInterfaceError: Commands out of sync; you can't run this command now
2025-03-15 16:28:03,182 - src.models.relational.tweets - ‚ÑπÔ∏è INFO - tweets.py:42 - Platforms already exist.
2025-03-15 16:28:03,185 - src.kafka.consumers.pipeline - ‚ùå ERROR - pipeline.py:75 - Error processing message: Commands out of sync; you can't run this command now
Traceback (most recent call last):
  File "C:\Users\Admin\PycharmProjects\SocialMediaPipeline\src\kafka\consumers\pipeline.py", line 60, in process_message
    self.tweet_model.insert_post_and_engagement_metrics(
  File "C:\Users\Admin\PycharmProjects\SocialMediaPipeline\src\models\relational\tweets.py", line 131, in insert_post_and_engagement_metrics
    self.execute_query(insert_post_query, params)
  File "C:\Users\Admin\PycharmProjects\SocialMediaPipeline\src\models\relational\tweets.py", line 59, in execute_query
    connection.commit()
  File "C:\Users\Admin\PycharmProjects\SocialMediaPipeline\.venv\Lib\site-packages\mysql\connector\connection_cext.py", line 609, in commit
    self._cmysql.commit()
_mysql_connector.MySQLInterfaceError: Commands out of sync; you can't run this command now
2025-03-15 16:28:03,186 - src.models.relational.tweets - ‚ÑπÔ∏è INFO - tweets.py:42 - Platforms already exist.
2025-03-15 16:28:03,189 - src.kafka.consumers.pipeline - ‚ùå ERROR - pipeline.py:75 - Error processing message: Commands out of sync; you can't run this command now
Traceback (most recent call last):
  File "C:\Users\Admin\PycharmProjects\SocialMediaPipeline\src\kafka\consumers\pipeline.py", line 60, in process_message
    self.tweet_model.insert_post_and_engagement_metrics(
  File "C:\Users\Admin\PycharmProjects\SocialMediaPipeline\src\models\relational\tweets.py", line 131, in insert_post_and_engagement_metrics
    self.execute_query(insert_post_query, params)
  File "C:\Users\Admin\PycharmProjects\SocialMediaPipeline\src\models\relational\tweets.py", line 59, in execute_query
    connection.commit()
  File "C:\Users\Admin\PycharmProjects\SocialMediaPipeline\.venv\Lib\site-packages\mysql\connector\connection_cext.py", line 609, in commit
    self._cmysql.commit()
_mysql_connector.MySQLInterfaceError: Commands out of sync; you can't run this command now
2025-03-15 16:28:03,191 - src.models.relational.tweets - ‚ÑπÔ∏è INFO - tweets.py:42 - Platforms already exist.
2025-03-15 16:28:03,194 - src.kafka.consumers.pipeline - ‚ùå ERROR - pipeline.py:75 - Error processing message: Commands out of sync; you can't run this command now
Traceback (most recent call last):
  File "C:\Users\Admin\PycharmProjects\SocialMediaPipeline\src\kafka\consumers\pipeline.py", line 60, in process_message
    self.tweet_model.insert_post_and_engagement_metrics(
  File "C:\Users\Admin\PycharmProjects\SocialMediaPipeline\src\models\relational\tweets.py", line 131, in insert_post_and_engagement_metrics
    self.execute_query(insert_post_query, params)
  File "C:\Users\Admin\PycharmProjects\SocialMediaPipeline\src\models\relational\tweets.py", line 59, in execute_query
    connection.commit()
  File "C:\Users\Admin\PycharmProjects\SocialMediaPipeline\.venv\Lib\site-packages\mysql\connector\connection_cext.py", line 609, in commit
    self._cmysql.commit()
_mysql_connector.MySQLInterfaceError: Commands out of sync; you can't run this command now
2025-03-15 16:28:03,197 - src.models.relational.tweets - ‚ÑπÔ∏è INFO - tweets.py:42 - Platforms already exist.
2025-03-15 16:28:03,200 - src.kafka.consumers.pipeline - ‚ùå ERROR - pipeline.py:75 - Error processing message: Commands out of sync; you can't run this command now
Traceback (most recent call last):
  File "C:\Users\Admin\PycharmProjects\SocialMediaPipeline\src\kafka\consumers\pipeline.py", line 60, in process_message
    self.tweet_model.insert_post_and_engagement_metrics(
  File "C:\Users\Admin\PycharmProjects\SocialMediaPipeline\src\models\relational\tweets.py", line 131, in insert_post_and_engagement_metrics
    self.execute_query(insert_post_query, params)
  File "C:\Users\Admin\PycharmProjects\SocialMediaPipeline\src\models\relational\tweets.py", line 59, in execute_query
    connection.commit()
  File "C:\Users\Admin\PycharmProjects\SocialMediaPipeline\.venv\Lib\site-packages\mysql\connector\connection_cext.py", line 609, in commit
    self._cmysql.commit()
_mysql_connector.MySQLInterfaceError: Commands out of sync; you can't run this command now
2025-03-15 16:28:03,201 - src.models.relational.tweets - ‚ÑπÔ∏è INFO - tweets.py:42 - Platforms already exist.
2025-03-15 16:28:03,203 - src.kafka.consumers.pipeline - ‚ùå ERROR - pipeline.py:75 - Error processing message: Commands out of sync; you can't run this command now
Traceback (most recent call last):
  File "C:\Users\Admin\PycharmProjects\SocialMediaPipeline\src\kafka\consumers\pipeline.py", line 60, in process_message
    self.tweet_model.insert_post_and_engagement_metrics(
  File "C:\Users\Admin\PycharmProjects\SocialMediaPipeline\src\models\relational\tweets.py", line 131, in insert_post_and_engagement_metrics
    self.execute_query(insert_post_query, params)
  File "C:\Users\Admin\PycharmProjects\SocialMediaPipeline\src\models\relational\tweets.py", line 59, in execute_query
    connection.commit()
  File "C:\Users\Admin\PycharmProjects\SocialMediaPipeline\.venv\Lib\site-packages\mysql\connector\connection_cext.py", line 609, in commit
    self._cmysql.commit()
_mysql_connector.MySQLInterfaceError: Commands out of sync; you can't run this command now
2025-03-15 16:28:03,206 - src.models.relational.tweets - ‚ÑπÔ∏è INFO - tweets.py:42 - Platforms already exist.
2025-03-15 16:28:03,207 - src.kafka.consumers.pipeline - ‚ùå ERROR - pipeline.py:75 - Error processing message: Commands out of sync; you can't run this command now
Traceback (most recent call last):
  File "C:\Users\Admin\PycharmProjects\SocialMediaPipeline\src\kafka\consumers\pipeline.py", line 60, in process_message
    self.tweet_model.insert_post_and_engagement_metrics(
  File "C:\Users\Admin\PycharmProjects\SocialMediaPipeline\src\models\relational\tweets.py", line 131, in insert_post_and_engagement_metrics
    self.execute_query(insert_post_query, params)
  File "C:\Users\Admin\PycharmProjects\SocialMediaPipeline\src\models\relational\tweets.py", line 59, in execute_query
    connection.commit()
  File "C:\Users\Admin\PycharmProjects\SocialMediaPipeline\.venv\Lib\site-packages\mysql\connector\connection_cext.py", line 609, in commit
    self._cmysql.commit()
_mysql_connector.MySQLInterfaceError: Commands out of sync; you can't run this command now
2025-03-15 16:28:03,210 - src.models.relational.tweets - ‚ÑπÔ∏è INFO - tweets.py:42 - Platforms already exist.
2025-03-15 16:28:03,211 - src.kafka.consumers.pipeline - ‚ùå ERROR - pipeline.py:75 - Error processing message: Commands out of sync; you can't run this command now
Traceback (most recent call last):
  File "C:\Users\Admin\PycharmProjects\SocialMediaPipeline\src\kafka\consumers\pipeline.py", line 60, in process_message
    self.tweet_model.insert_post_and_engagement_metrics(
  File "C:\Users\Admin\PycharmProjects\SocialMediaPipeline\src\models\relational\tweets.py", line 131, in insert_post_and_engagement_metrics
    self.execute_query(insert_post_query, params)
  File "C:\Users\Admin\PycharmProjects\SocialMediaPipeline\src\models\relational\tweets.py", line 59, in execute_query
    connection.commit()
  File "C:\Users\Admin\PycharmProjects\SocialMediaPipeline\.venv\Lib\site-packages\mysql\connector\connection_cext.py", line 609, in commit
    self._cmysql.commit()
_mysql_connector.MySQLInterfaceError: Commands out of sync; you can't run this command now
2025-03-15 16:28:03,214 - src.models.relational.tweets - ‚ÑπÔ∏è INFO - tweets.py:42 - Platforms already exist.
2025-03-15 16:28:03,216 - src.kafka.consumers.pipeline - ‚ùå ERROR - pipeline.py:75 - Error processing message: Commands out of sync; you can't run this command now
Traceback (most recent call last):
  File "C:\Users\Admin\PycharmProjects\SocialMediaPipeline\src\kafka\consumers\pipeline.py", line 60, in process_message
    self.tweet_model.insert_post_and_engagement_metrics(
  File "C:\Users\Admin\PycharmProjects\SocialMediaPipeline\src\models\relational\tweets.py", line 131, in insert_post_and_engagement_metrics
    self.execute_query(insert_post_query, params)
  File "C:\Users\Admin\PycharmProjects\SocialMediaPipeline\src\models\relational\tweets.py", line 59, in execute_query
    connection.commit()
  File "C:\Users\Admin\PycharmProjects\SocialMediaPipeline\.venv\Lib\site-packages\mysql\connector\connection_cext.py", line 609, in commit
    self._cmysql.commit()
_mysql_connector.MySQLInterfaceError: Commands out of sync; you can't run this command now
2025-03-15 16:28:03,219 - src.models.relational.tweets - ‚ÑπÔ∏è INFO - tweets.py:42 - Platforms already exist.
2025-03-15 16:28:03,220 - src.kafka.consumers.pipeline - ‚ùå ERROR - pipeline.py:75 - Error processing message: Commands out of sync; you can't run this command now
Traceback (most recent call last):
  File "C:\Users\Admin\PycharmProjects\SocialMediaPipeline\src\kafka\consumers\pipeline.py", line 60, in process_message
    self.tweet_model.insert_post_and_engagement_metrics(
  File "C:\Users\Admin\PycharmProjects\SocialMediaPipeline\src\models\relational\tweets.py", line 131, in insert_post_and_engagement_metrics
    self.execute_query(insert_post_query, params)
  File "C:\Users\Admin\PycharmProjects\SocialMediaPipeline\src\models\relational\tweets.py", line 59, in execute_query
    connection.commit()
  File "C:\Users\Admin\PycharmProjects\SocialMediaPipeline\.venv\Lib\site-packages\mysql\connector\connection_cext.py", line 609, in commit
    self._cmysql.commit()
_mysql_connector.MySQLInterfaceError: Commands out of sync; you can't run this command now
2025-03-15 16:28:03,223 - src.models.relational.tweets - ‚ÑπÔ∏è INFO - tweets.py:42 - Platforms already exist.
2025-03-15 16:28:03,224 - src.kafka.consumers.pipeline - ‚ùå ERROR - pipeline.py:75 - Error processing message: Commands out of sync; you can't run this command now
Traceback (most recent call last):
  File "C:\Users\Admin\PycharmProjects\SocialMediaPipeline\src\kafka\consumers\pipeline.py", line 60, in process_message
    self.tweet_model.insert_post_and_engagement_metrics(
  File "C:\Users\Admin\PycharmProjects\SocialMediaPipeline\src\models\relational\tweets.py", line 131, in insert_post_and_engagement_metrics
    self.execute_query(insert_post_query, params)
  File "C:\Users\Admin\PycharmProjects\SocialMediaPipeline\src\models\relational\tweets.py", line 59, in execute_query
    connection.commit()
  File "C:\Users\Admin\PycharmProjects\SocialMediaPipeline\.venv\Lib\site-packages\mysql\connector\connection_cext.py", line 609, in commit
    self._cmysql.commit()
_mysql_connector.MySQLInterfaceError: Commands out of sync; you can't run this command now
2025-03-15 16:28:03,228 - src.models.relational.tweets - ‚ÑπÔ∏è INFO - tweets.py:42 - Platforms already exist.
2025-03-15 16:28:03,229 - src.kafka.consumers.pipeline - ‚ùå ERROR - pipeline.py:75 - Error processing message: Commands out of sync; you can't run this command now
Traceback (most recent call last):
  File "C:\Users\Admin\PycharmProjects\SocialMediaPipeline\src\kafka\consumers\pipeline.py", line 60, in process_message
    self.tweet_model.insert_post_and_engagement_metrics(
  File "C:\Users\Admin\PycharmProjects\SocialMediaPipeline\src\models\relational\tweets.py", line 131, in insert_post_and_engagement_metrics
    self.execute_query(insert_post_query, params)
  File "C:\Users\Admin\PycharmProjects\SocialMediaPipeline\src\models\relational\tweets.py", line 59, in execute_query
    connection.commit()
  File "C:\Users\Admin\PycharmProjects\SocialMediaPipeline\.venv\Lib\site-packages\mysql\connector\connection_cext.py", line 609, in commit
    self._cmysql.commit()
_mysql_connector.MySQLInterfaceError: Commands out of sync; you can't run this command now
2025-03-15 16:28:03,232 - src.models.relational.tweets - ‚ÑπÔ∏è INFO - tweets.py:42 - Platforms already exist.
2025-03-15 16:28:03,234 - src.kafka.consumers.pipeline - ‚ùå ERROR - pipeline.py:75 - Error processing message: Commands out of sync; you can't run this command now
Traceback (most recent call last):
  File "C:\Users\Admin\PycharmProjects\SocialMediaPipeline\src\kafka\consumers\pipeline.py", line 60, in process_message
    self.tweet_model.insert_post_and_engagement_metrics(
  File "C:\Users\Admin\PycharmProjects\SocialMediaPipeline\src\models\relational\tweets.py", line 131, in insert_post_and_engagement_metrics
    self.execute_query(insert_post_query, params)
  File "C:\Users\Admin\PycharmProjects\SocialMediaPipeline\src\models\relational\tweets.py", line 59, in execute_query
    connection.commit()
  File "C:\Users\Admin\PycharmProjects\SocialMediaPipeline\.venv\Lib\site-packages\mysql\connector\connection_cext.py", line 609, in commit
    self._cmysql.commit()
_mysql_connector.MySQLInterfaceError: Commands out of sync; you can't run this command now
2025-03-15 16:28:03,237 - src.models.relational.tweets - ‚ÑπÔ∏è INFO - tweets.py:42 - Platforms already exist.
2025-03-15 16:28:03,238 - src.kafka.consumers.pipeline - ‚ùå ERROR - pipeline.py:75 - Error processing message: Commands out of sync; you can't run this command now
Traceback (most recent call last):
  File "C:\Users\Admin\PycharmProjects\SocialMediaPipeline\src\kafka\consumers\pipeline.py", line 60, in process_message
    self.tweet_model.insert_post_and_engagement_metrics(
  File "C:\Users\Admin\PycharmProjects\SocialMediaPipeline\src\models\relational\tweets.py", line 131, in insert_post_and_engagement_metrics
    self.execute_query(insert_post_query, params)
  File "C:\Users\Admin\PycharmProjects\SocialMediaPipeline\src\models\relational\tweets.py", line 59, in execute_query
    connection.commit()
  File "C:\Users\Admin\PycharmProjects\SocialMediaPipeline\.venv\Lib\site-packages\mysql\connector\connection_cext.py", line 609, in commit
    self._cmysql.commit()
_mysql_connector.MySQLInterfaceError: Commands out of sync; you can't run this command now
2025-03-15 16:28:03,241 - src.models.relational.tweets - ‚ÑπÔ∏è INFO - tweets.py:42 - Platforms already exist.
2025-03-15 16:28:03,242 - src.kafka.consumers.pipeline - ‚ùå ERROR - pipeline.py:75 - Error processing message: Commands out of sync; you can't run this command now
Traceback (most recent call last):
  File "C:\Users\Admin\PycharmProjects\SocialMediaPipeline\src\kafka\consumers\pipeline.py", line 60, in process_message
    self.tweet_model.insert_post_and_engagement_metrics(
  File "C:\Users\Admin\PycharmProjects\SocialMediaPipeline\src\models\relational\tweets.py", line 131, in insert_post_and_engagement_metrics
    self.execute_query(insert_post_query, params)
  File "C:\Users\Admin\PycharmProjects\SocialMediaPipeline\src\models\relational\tweets.py", line 59, in execute_query
    connection.commit()
  File "C:\Users\Admin\PycharmProjects\SocialMediaPipeline\.venv\Lib\site-packages\mysql\connector\connection_cext.py", line 609, in commit
    self._cmysql.commit()
_mysql_connector.MySQLInterfaceError: Commands out of sync; you can't run this command now
2025-03-15 16:28:03,244 - src.models.relational.tweets - ‚ÑπÔ∏è INFO - tweets.py:42 - Platforms already exist.
2025-03-15 16:28:03,246 - src.kafka.consumers.pipeline - ‚ùå ERROR - pipeline.py:75 - Error processing message: Commands out of sync; you can't run this command now
Traceback (most recent call last):
  File "C:\Users\Admin\PycharmProjects\SocialMediaPipeline\src\kafka\consumers\pipeline.py", line 60, in process_message
    self.tweet_model.insert_post_and_engagement_metrics(
  File "C:\Users\Admin\PycharmProjects\SocialMediaPipeline\src\models\relational\tweets.py", line 131, in insert_post_and_engagement_metrics
    self.execute_query(insert_post_query, params)
  File "C:\Users\Admin\PycharmProjects\SocialMediaPipeline\src\models\relational\tweets.py", line 59, in execute_query
    connection.commit()
  File "C:\Users\Admin\PycharmProjects\SocialMediaPipeline\.venv\Lib\site-packages\mysql\connector\connection_cext.py", line 609, in commit
    self._cmysql.commit()
_mysql_connector.MySQLInterfaceError: Commands out of sync; you can't run this command now
2025-03-15 16:28:03,249 - src.models.relational.tweets - ‚ÑπÔ∏è INFO - tweets.py:42 - Platforms already exist.
2025-03-15 16:28:03,251 - src.kafka.consumers.pipeline - ‚ùå ERROR - pipeline.py:75 - Error processing message: Commands out of sync; you can't run this command now
Traceback (most recent call last):
  File "C:\Users\Admin\PycharmProjects\SocialMediaPipeline\src\kafka\consumers\pipeline.py", line 60, in process_message
    self.tweet_model.insert_post_and_engagement_metrics(
  File "C:\Users\Admin\PycharmProjects\SocialMediaPipeline\src\models\relational\tweets.py", line 131, in insert_post_and_engagement_metrics
    self.execute_query(insert_post_query, params)
  File "C:\Users\Admin\PycharmProjects\SocialMediaPipeline\src\models\relational\tweets.py", line 59, in execute_query
    connection.commit()
  File "C:\Users\Admin\PycharmProjects\SocialMediaPipeline\.venv\Lib\site-packages\mysql\connector\connection_cext.py", line 609, in commit
    self._cmysql.commit()
_mysql_connector.MySQLInterfaceError: Commands out of sync; you can't run this command now
2025-03-15 16:28:03,254 - src.models.relational.tweets - ‚ÑπÔ∏è INFO - tweets.py:42 - Platforms already exist.
2025-03-15 16:28:03,255 - src.kafka.consumers.pipeline - ‚ùå ERROR - pipeline.py:75 - Error processing message: Commands out of sync; you can't run this command now
Traceback (most recent call last):
  File "C:\Users\Admin\PycharmProjects\SocialMediaPipeline\src\kafka\consumers\pipeline.py", line 60, in process_message
    self.tweet_model.insert_post_and_engagement_metrics(
  File "C:\Users\Admin\PycharmProjects\SocialMediaPipeline\src\models\relational\tweets.py", line 131, in insert_post_and_engagement_metrics
    self.execute_query(insert_post_query, params)
  File "C:\Users\Admin\PycharmProjects\SocialMediaPipeline\src\models\relational\tweets.py", line 59, in execute_query
    connection.commit()
  File "C:\Users\Admin\PycharmProjects\SocialMediaPipeline\.venv\Lib\site-packages\mysql\connector\connection_cext.py", line 609, in commit
    self._cmysql.commit()
_mysql_connector.MySQLInterfaceError: Commands out of sync; you can't run this command now
2025-03-15 16:28:03,257 - src.models.relational.tweets - ‚ÑπÔ∏è INFO - tweets.py:42 - Platforms already exist.
2025-03-15 16:28:03,260 - src.kafka.consumers.pipeline - ‚ùå ERROR - pipeline.py:75 - Error processing message: Commands out of sync; you can't run this command now
Traceback (most recent call last):
  File "C:\Users\Admin\PycharmProjects\SocialMediaPipeline\src\kafka\consumers\pipeline.py", line 60, in process_message
    self.tweet_model.insert_post_and_engagement_metrics(
  File "C:\Users\Admin\PycharmProjects\SocialMediaPipeline\src\models\relational\tweets.py", line 131, in insert_post_and_engagement_metrics
    self.execute_query(insert_post_query, params)
  File "C:\Users\Admin\PycharmProjects\SocialMediaPipeline\src\models\relational\tweets.py", line 59, in execute_query
    connection.commit()
  File "C:\Users\Admin\PycharmProjects\SocialMediaPipeline\.venv\Lib\site-packages\mysql\connector\connection_cext.py", line 609, in commit
    self._cmysql.commit()
_mysql_connector.MySQLInterfaceError: Commands out of sync; you can't run this command now
2025-03-15 16:28:03,261 - src.models.relational.tweets - ‚ÑπÔ∏è INFO - tweets.py:42 - Platforms already exist.
2025-03-15 16:28:03,264 - src.kafka.consumers.pipeline - ‚ùå ERROR - pipeline.py:75 - Error processing message: Commands out of sync; you can't run this command now
Traceback (most recent call last):
  File "C:\Users\Admin\PycharmProjects\SocialMediaPipeline\src\kafka\consumers\pipeline.py", line 60, in process_message
    self.tweet_model.insert_post_and_engagement_metrics(
  File "C:\Users\Admin\PycharmProjects\SocialMediaPipeline\src\models\relational\tweets.py", line 131, in insert_post_and_engagement_metrics
    self.execute_query(insert_post_query, params)
  File "C:\Users\Admin\PycharmProjects\SocialMediaPipeline\src\models\relational\tweets.py", line 59, in execute_query
    connection.commit()
  File "C:\Users\Admin\PycharmProjects\SocialMediaPipeline\.venv\Lib\site-packages\mysql\connector\connection_cext.py", line 609, in commit
    self._cmysql.commit()
_mysql_connector.MySQLInterfaceError: Commands out of sync; you can't run this command now
2025-03-15 16:28:03,267 - src.models.relational.tweets - ‚ÑπÔ∏è INFO - tweets.py:42 - Platforms already exist.
2025-03-15 16:28:03,268 - src.kafka.consumers.pipeline - ‚ùå ERROR - pipeline.py:75 - Error processing message: Commands out of sync; you can't run this command now
Traceback (most recent call last):
  File "C:\Users\Admin\PycharmProjects\SocialMediaPipeline\src\kafka\consumers\pipeline.py", line 60, in process_message
    self.tweet_model.insert_post_and_engagement_metrics(
  File "C:\Users\Admin\PycharmProjects\SocialMediaPipeline\src\models\relational\tweets.py", line 131, in insert_post_and_engagement_metrics
    self.execute_query(insert_post_query, params)
  File "C:\Users\Admin\PycharmProjects\SocialMediaPipeline\src\models\relational\tweets.py", line 59, in execute_query
    connection.commit()
  File "C:\Users\Admin\PycharmProjects\SocialMediaPipeline\.venv\Lib\site-packages\mysql\connector\connection_cext.py", line 609, in commit
    self._cmysql.commit()
_mysql_connector.MySQLInterfaceError: Commands out of sync; you can't run this command now
2025-03-15 16:28:03,271 - src.models.relational.tweets - ‚ÑπÔ∏è INFO - tweets.py:42 - Platforms already exist.
2025-03-15 16:28:03,272 - src.kafka.consumers.pipeline - ‚ùå ERROR - pipeline.py:75 - Error processing message: Commands out of sync; you can't run this command now
Traceback (most recent call last):
  File "C:\Users\Admin\PycharmProjects\SocialMediaPipeline\src\kafka\consumers\pipeline.py", line 60, in process_message
    self.tweet_model.insert_post_and_engagement_metrics(
  File "C:\Users\Admin\PycharmProjects\SocialMediaPipeline\src\models\relational\tweets.py", line 131, in insert_post_and_engagement_metrics
    self.execute_query(insert_post_query, params)
  File "C:\Users\Admin\PycharmProjects\SocialMediaPipeline\src\models\relational\tweets.py", line 59, in execute_query
    connection.commit()
  File "C:\Users\Admin\PycharmProjects\SocialMediaPipeline\.venv\Lib\site-packages\mysql\connector\connection_cext.py", line 609, in commit
    self._cmysql.commit()
_mysql_connector.MySQLInterfaceError: Commands out of sync; you can't run this command now
2025-03-15 16:28:03,275 - src.models.relational.tweets - ‚ÑπÔ∏è INFO - tweets.py:42 - Platforms already exist.
2025-03-15 16:28:03,276 - src.kafka.consumers.pipeline - ‚ùå ERROR - pipeline.py:75 - Error processing message: Commands out of sync; you can't run this command now
Traceback (most recent call last):
  File "C:\Users\Admin\PycharmProjects\SocialMediaPipeline\src\kafka\consumers\pipeline.py", line 60, in process_message
    self.tweet_model.insert_post_and_engagement_metrics(
  File "C:\Users\Admin\PycharmProjects\SocialMediaPipeline\src\models\relational\tweets.py", line 131, in insert_post_and_engagement_metrics
    self.execute_query(insert_post_query, params)
  File "C:\Users\Admin\PycharmProjects\SocialMediaPipeline\src\models\relational\tweets.py", line 59, in execute_query
    connection.commit()
  File "C:\Users\Admin\PycharmProjects\SocialMediaPipeline\.venv\Lib\site-packages\mysql\connector\connection_cext.py", line 609, in commit
    self._cmysql.commit()
_mysql_connector.MySQLInterfaceError: Commands out of sync; you can't run this command now
2025-03-15 16:28:03,280 - src.models.relational.tweets - ‚ÑπÔ∏è INFO - tweets.py:42 - Platforms already exist.
2025-03-15 16:28:03,281 - src.kafka.consumers.pipeline - ‚ùå ERROR - pipeline.py:75 - Error processing message: Commands out of sync; you can't run this command now
Traceback (most recent call last):
  File "C:\Users\Admin\PycharmProjects\SocialMediaPipeline\src\kafka\consumers\pipeline.py", line 60, in process_message
    self.tweet_model.insert_post_and_engagement_metrics(
  File "C:\Users\Admin\PycharmProjects\SocialMediaPipeline\src\models\relational\tweets.py", line 131, in insert_post_and_engagement_metrics
    self.execute_query(insert_post_query, params)
  File "C:\Users\Admin\PycharmProjects\SocialMediaPipeline\src\models\relational\tweets.py", line 59, in execute_query
    connection.commit()
  File "C:\Users\Admin\PycharmProjects\SocialMediaPipeline\.venv\Lib\site-packages\mysql\connector\connection_cext.py", line 609, in commit
    self._cmysql.commit()
_mysql_connector.MySQLInterfaceError: Commands out of sync; you can't run this command now
2025-03-15 16:28:03,283 - src.models.relational.tweets - ‚ÑπÔ∏è INFO - tweets.py:42 - Platforms already exist.
2025-03-15 16:28:03,285 - src.kafka.consumers.pipeline - ‚ùå ERROR - pipeline.py:75 - Error processing message: Commands out of sync; you can't run this command now
Traceback (most recent call last):
  File "C:\Users\Admin\PycharmProjects\SocialMediaPipeline\src\kafka\consumers\pipeline.py", line 60, in process_message
    self.tweet_model.insert_post_and_engagement_metrics(
  File "C:\Users\Admin\PycharmProjects\SocialMediaPipeline\src\models\relational\tweets.py", line 131, in insert_post_and_engagement_metrics
    self.execute_query(insert_post_query, params)
  File "C:\Users\Admin\PycharmProjects\SocialMediaPipeline\src\models\relational\tweets.py", line 59, in execute_query
    connection.commit()
  File "C:\Users\Admin\PycharmProjects\SocialMediaPipeline\.venv\Lib\site-packages\mysql\connector\connection_cext.py", line 609, in commit
    self._cmysql.commit()
_mysql_connector.MySQLInterfaceError: Commands out of sync; you can't run this command now
2025-03-15 16:28:03,289 - src.models.relational.tweets - ‚ÑπÔ∏è INFO - tweets.py:42 - Platforms already exist.
2025-03-15 16:28:03,290 - src.kafka.consumers.pipeline - ‚ùå ERROR - pipeline.py:75 - Error processing message: Commands out of sync; you can't run this command now
Traceback (most recent call last):
  File "C:\Users\Admin\PycharmProjects\SocialMediaPipeline\src\kafka\consumers\pipeline.py", line 60, in process_message
    self.tweet_model.insert_post_and_engagement_metrics(
  File "C:\Users\Admin\PycharmProjects\SocialMediaPipeline\src\models\relational\tweets.py", line 131, in insert_post_and_engagement_metrics
    self.execute_query(insert_post_query, params)
  File "C:\Users\Admin\PycharmProjects\SocialMediaPipeline\src\models\relational\tweets.py", line 59, in execute_query
    connection.commit()
  File "C:\Users\Admin\PycharmProjects\SocialMediaPipeline\.venv\Lib\site-packages\mysql\connector\connection_cext.py", line 609, in commit
    self._cmysql.commit()
_mysql_connector.MySQLInterfaceError: Commands out of sync; you can't run this command now
2025-03-15 16:28:03,292 - src.models.relational.tweets - ‚ÑπÔ∏è INFO - tweets.py:42 - Platforms already exist.
2025-03-15 16:28:03,294 - src.kafka.consumers.pipeline - ‚ùå ERROR - pipeline.py:75 - Error processing message: Commands out of sync; you can't run this command now
Traceback (most recent call last):
  File "C:\Users\Admin\PycharmProjects\SocialMediaPipeline\src\kafka\consumers\pipeline.py", line 60, in process_message
    self.tweet_model.insert_post_and_engagement_metrics(
  File "C:\Users\Admin\PycharmProjects\SocialMediaPipeline\src\models\relational\tweets.py", line 131, in insert_post_and_engagement_metrics
    self.execute_query(insert_post_query, params)
  File "C:\Users\Admin\PycharmProjects\SocialMediaPipeline\src\models\relational\tweets.py", line 59, in execute_query
    connection.commit()
  File "C:\Users\Admin\PycharmProjects\SocialMediaPipeline\.venv\Lib\site-packages\mysql\connector\connection_cext.py", line 609, in commit
    self._cmysql.commit()
_mysql_connector.MySQLInterfaceError: Commands out of sync; you can't run this command now
2025-03-15 16:28:03,297 - src.models.relational.tweets - ‚ÑπÔ∏è INFO - tweets.py:42 - Platforms already exist.
2025-03-15 16:28:03,299 - src.kafka.consumers.pipeline - ‚ùå ERROR - pipeline.py:75 - Error processing message: Commands out of sync; you can't run this command now
Traceback (most recent call last):
  File "C:\Users\Admin\PycharmProjects\SocialMediaPipeline\src\kafka\consumers\pipeline.py", line 60, in process_message
    self.tweet_model.insert_post_and_engagement_metrics(
  File "C:\Users\Admin\PycharmProjects\SocialMediaPipeline\src\models\relational\tweets.py", line 131, in insert_post_and_engagement_metrics
    self.execute_query(insert_post_query, params)
  File "C:\Users\Admin\PycharmProjects\SocialMediaPipeline\src\models\relational\tweets.py", line 59, in execute_query
    connection.commit()
  File "C:\Users\Admin\PycharmProjects\SocialMediaPipeline\.venv\Lib\site-packages\mysql\connector\connection_cext.py", line 609, in commit
    self._cmysql.commit()
_mysql_connector.MySQLInterfaceError: Commands out of sync; you can't run this command now
2025-03-15 16:28:03,301 - src.models.relational.tweets - ‚ÑπÔ∏è INFO - tweets.py:42 - Platforms already exist.
2025-03-15 16:28:03,303 - src.kafka.consumers.pipeline - ‚ùå ERROR - pipeline.py:75 - Error processing message: Commands out of sync; you can't run this command now
Traceback (most recent call last):
  File "C:\Users\Admin\PycharmProjects\SocialMediaPipeline\src\kafka\consumers\pipeline.py", line 60, in process_message
    self.tweet_model.insert_post_and_engagement_metrics(
  File "C:\Users\Admin\PycharmProjects\SocialMediaPipeline\src\models\relational\tweets.py", line 131, in insert_post_and_engagement_metrics
    self.execute_query(insert_post_query, params)
  File "C:\Users\Admin\PycharmProjects\SocialMediaPipeline\src\models\relational\tweets.py", line 59, in execute_query
    connection.commit()
  File "C:\Users\Admin\PycharmProjects\SocialMediaPipeline\.venv\Lib\site-packages\mysql\connector\connection_cext.py", line 609, in commit
    self._cmysql.commit()
_mysql_connector.MySQLInterfaceError: Commands out of sync; you can't run this command now
2025-03-15 16:28:03,306 - src.models.relational.tweets - ‚ÑπÔ∏è INFO - tweets.py:42 - Platforms already exist.
2025-03-15 16:28:03,307 - src.kafka.consumers.pipeline - ‚ùå ERROR - pipeline.py:75 - Error processing message: Commands out of sync; you can't run this command now
Traceback (most recent call last):
  File "C:\Users\Admin\PycharmProjects\SocialMediaPipeline\src\kafka\consumers\pipeline.py", line 60, in process_message
    self.tweet_model.insert_post_and_engagement_metrics(
  File "C:\Users\Admin\PycharmProjects\SocialMediaPipeline\src\models\relational\tweets.py", line 131, in insert_post_and_engagement_metrics
    self.execute_query(insert_post_query, params)
  File "C:\Users\Admin\PycharmProjects\SocialMediaPipeline\src\models\relational\tweets.py", line 59, in execute_query
    connection.commit()
  File "C:\Users\Admin\PycharmProjects\SocialMediaPipeline\.venv\Lib\site-packages\mysql\connector\connection_cext.py", line 609, in commit
    self._cmysql.commit()
_mysql_connector.MySQLInterfaceError: Commands out of sync; you can't run this command now
2025-03-15 16:28:03,310 - src.models.relational.tweets - ‚ÑπÔ∏è INFO - tweets.py:42 - Platforms already exist.
2025-03-15 16:28:03,312 - src.kafka.consumers.pipeline - ‚ùå ERROR - pipeline.py:75 - Error processing message: Commands out of sync; you can't run this command now
Traceback (most recent call last):
  File "C:\Users\Admin\PycharmProjects\SocialMediaPipeline\src\kafka\consumers\pipeline.py", line 60, in process_message
    self.tweet_model.insert_post_and_engagement_metrics(
  File "C:\Users\Admin\PycharmProjects\SocialMediaPipeline\src\models\relational\tweets.py", line 131, in insert_post_and_engagement_metrics
    self.execute_query(insert_post_query, params)
  File "C:\Users\Admin\PycharmProjects\SocialMediaPipeline\src\models\relational\tweets.py", line 59, in execute_query
    connection.commit()
  File "C:\Users\Admin\PycharmProjects\SocialMediaPipeline\.venv\Lib\site-packages\mysql\connector\connection_cext.py", line 609, in commit
    self._cmysql.commit()
_mysql_connector.MySQLInterfaceError: Commands out of sync; you can't run this command now
2025-03-15 16:28:03,314 - src.models.relational.tweets - ‚ÑπÔ∏è INFO - tweets.py:42 - Platforms already exist.
2025-03-15 16:28:03,317 - src.kafka.consumers.pipeline - ‚ùå ERROR - pipeline.py:75 - Error processing message: Commands out of sync; you can't run this command now
Traceback (most recent call last):
  File "C:\Users\Admin\PycharmProjects\SocialMediaPipeline\src\kafka\consumers\pipeline.py", line 60, in process_message
    self.tweet_model.insert_post_and_engagement_metrics(
  File "C:\Users\Admin\PycharmProjects\SocialMediaPipeline\src\models\relational\tweets.py", line 131, in insert_post_and_engagement_metrics
    self.execute_query(insert_post_query, params)
  File "C:\Users\Admin\PycharmProjects\SocialMediaPipeline\src\models\relational\tweets.py", line 59, in execute_query
    connection.commit()
  File "C:\Users\Admin\PycharmProjects\SocialMediaPipeline\.venv\Lib\site-packages\mysql\connector\connection_cext.py", line 609, in commit
    self._cmysql.commit()
_mysql_connector.MySQLInterfaceError: Commands out of sync; you can't run this command now
2025-03-15 16:28:03,318 - src.models.relational.tweets - ‚ÑπÔ∏è INFO - tweets.py:42 - Platforms already exist.
2025-03-15 16:28:03,321 - src.kafka.consumers.pipeline - ‚ùå ERROR - pipeline.py:75 - Error processing message: Commands out of sync; you can't run this command now
Traceback (most recent call last):
  File "C:\Users\Admin\PycharmProjects\SocialMediaPipeline\src\kafka\consumers\pipeline.py", line 60, in process_message
    self.tweet_model.insert_post_and_engagement_metrics(
  File "C:\Users\Admin\PycharmProjects\SocialMediaPipeline\src\models\relational\tweets.py", line 131, in insert_post_and_engagement_metrics
    self.execute_query(insert_post_query, params)
  File "C:\Users\Admin\PycharmProjects\SocialMediaPipeline\src\models\relational\tweets.py", line 59, in execute_query
    connection.commit()
  File "C:\Users\Admin\PycharmProjects\SocialMediaPipeline\.venv\Lib\site-packages\mysql\connector\connection_cext.py", line 609, in commit
    self._cmysql.commit()
_mysql_connector.MySQLInterfaceError: Commands out of sync; you can't run this command now
2025-03-15 16:28:03,324 - src.models.relational.tweets - ‚ÑπÔ∏è INFO - tweets.py:42 - Platforms already exist.
2025-03-15 16:28:03,325 - src.kafka.consumers.pipeline - ‚ùå ERROR - pipeline.py:75 - Error processing message: Commands out of sync; you can't run this command now
Traceback (most recent call last):
  File "C:\Users\Admin\PycharmProjects\SocialMediaPipeline\src\kafka\consumers\pipeline.py", line 60, in process_message
    self.tweet_model.insert_post_and_engagement_metrics(
  File "C:\Users\Admin\PycharmProjects\SocialMediaPipeline\src\models\relational\tweets.py", line 131, in insert_post_and_engagement_metrics
    self.execute_query(insert_post_query, params)
  File "C:\Users\Admin\PycharmProjects\SocialMediaPipeline\src\models\relational\tweets.py", line 59, in execute_query
    connection.commit()
  File "C:\Users\Admin\PycharmProjects\SocialMediaPipeline\.venv\Lib\site-packages\mysql\connector\connection_cext.py", line 609, in commit
    self._cmysql.commit()
_mysql_connector.MySQLInterfaceError: Commands out of sync; you can't run this command now
2025-03-15 16:28:03,328 - src.models.relational.tweets - ‚ÑπÔ∏è INFO - tweets.py:42 - Platforms already exist.
2025-03-15 16:28:03,329 - src.kafka.consumers.pipeline - ‚ùå ERROR - pipeline.py:75 - Error processing message: Commands out of sync; you can't run this command now
Traceback (most recent call last):
  File "C:\Users\Admin\PycharmProjects\SocialMediaPipeline\src\kafka\consumers\pipeline.py", line 60, in process_message
    self.tweet_model.insert_post_and_engagement_metrics(
  File "C:\Users\Admin\PycharmProjects\SocialMediaPipeline\src\models\relational\tweets.py", line 131, in insert_post_and_engagement_metrics
    self.execute_query(insert_post_query, params)
  File "C:\Users\Admin\PycharmProjects\SocialMediaPipeline\src\models\relational\tweets.py", line 59, in execute_query
    connection.commit()
  File "C:\Users\Admin\PycharmProjects\SocialMediaPipeline\.venv\Lib\site-packages\mysql\connector\connection_cext.py", line 609, in commit
    self._cmysql.commit()
_mysql_connector.MySQLInterfaceError: Commands out of sync; you can't run this command now
2025-03-15 16:28:03,332 - src.models.relational.tweets - ‚ÑπÔ∏è INFO - tweets.py:42 - Platforms already exist.
2025-03-15 16:28:03,333 - src.kafka.consumers.pipeline - ‚ùå ERROR - pipeline.py:75 - Error processing message: Commands out of sync; you can't run this command now
Traceback (most recent call last):
  File "C:\Users\Admin\PycharmProjects\SocialMediaPipeline\src\kafka\consumers\pipeline.py", line 60, in process_message
    self.tweet_model.insert_post_and_engagement_metrics(
  File "C:\Users\Admin\PycharmProjects\SocialMediaPipeline\src\models\relational\tweets.py", line 131, in insert_post_and_engagement_metrics
    self.execute_query(insert_post_query, params)
  File "C:\Users\Admin\PycharmProjects\SocialMediaPipeline\src\models\relational\tweets.py", line 59, in execute_query
    connection.commit()
  File "C:\Users\Admin\PycharmProjects\SocialMediaPipeline\.venv\Lib\site-packages\mysql\connector\connection_cext.py", line 609, in commit
    self._cmysql.commit()
_mysql_connector.MySQLInterfaceError: Commands out of sync; you can't run this command now
2025-03-15 16:28:03,335 - src.models.relational.tweets - ‚ÑπÔ∏è INFO - tweets.py:42 - Platforms already exist.
2025-03-15 16:28:03,337 - src.kafka.consumers.pipeline - ‚ùå ERROR - pipeline.py:75 - Error processing message: Commands out of sync; you can't run this command now
Traceback (most recent call last):
  File "C:\Users\Admin\PycharmProjects\SocialMediaPipeline\src\kafka\consumers\pipeline.py", line 60, in process_message
    self.tweet_model.insert_post_and_engagement_metrics(
  File "C:\Users\Admin\PycharmProjects\SocialMediaPipeline\src\models\relational\tweets.py", line 131, in insert_post_and_engagement_metrics
    self.execute_query(insert_post_query, params)
  File "C:\Users\Admin\PycharmProjects\SocialMediaPipeline\src\models\relational\tweets.py", line 59, in execute_query
    connection.commit()
  File "C:\Users\Admin\PycharmProjects\SocialMediaPipeline\.venv\Lib\site-packages\mysql\connector\connection_cext.py", line 609, in commit
    self._cmysql.commit()
_mysql_connector.MySQLInterfaceError: Commands out of sync; you can't run this command now
2025-03-15 16:28:33,631 - src.kafka.consumers.pipeline - ‚ÑπÔ∏è INFO - pipeline.py:219 - Storage Consumer finished.
2025-03-15 16:28:33,631 - src.kafka.consumers.pipeline - ‚ÑπÔ∏è INFO - pipeline.py:222 - Starting Word Frequency Consumer...
2025-03-15 16:29:06,934 - src.kafka.consumers.pipeline - ‚ÑπÔ∏è INFO - pipeline.py:127 - Top 20 word frequencies saved to C:\Users\Admin\PycharmProjects\SocialMediaPipeline\data\word_frequencies.json
2025-03-15 16:29:06,974 - src.models.relational.tweets - ‚ÑπÔ∏è INFO - tweets.py:173 - Word frequencies inserted successfully.
2025-03-15 16:29:06,974 - src.kafka.consumers.pipeline - ‚ÑπÔ∏è INFO - pipeline.py:131 - Word frequencies saved to database
2025-03-15 16:29:06,974 - src.kafka.consumers.pipeline - ‚ÑπÔ∏è INFO - pipeline.py:228 - Starting Engagement Metrics Consumer...
2025-03-15 16:29:06,974 - src.kafka.consumers.pipeline - ‚ö†Ô∏è WARNING - pipeline.py:148 - No messages in shared store to process
2025-03-15 16:29:06,974 - src.kafka.consumers.pipeline - ‚ö†Ô∏è WARNING - pipeline.py:176 - No engagement data collected to save.
2025-03-15 16:29:06,975 - src.kafka.consumers.pipeline - ‚ÑπÔ∏è INFO - pipeline.py:234 - Pipeline run completed
2025-03-15 16:29:06,976 - root - ‚ÑπÔ∏è INFO - main.py:92 - Pipeline run completed
